2018-07-29 09:09:28,212 ERROR: Exception on / [GET] [in /home/allin/Software/anaconda/envs/allen_blog/lib/python3.6/site-packages/flask/app.py:1761]
Traceback (most recent call last):
  File "/home/allin/Software/anaconda/envs/allen_blog/lib/python3.6/site-packages/sqlalchemy/engine/base.py", line 1193, in _execute_context
    context)
  File "/home/allin/Software/anaconda/envs/allen_blog/lib/python3.6/site-packages/sqlalchemy/engine/default.py", line 509, in do_execute
    cursor.execute(statement, parameters)
sqlite3.OperationalError: no such table: parent

The above exception was the direct cause of the following exception:

Traceback (most recent call last):
  File "/home/allin/Software/anaconda/envs/allen_blog/lib/python3.6/site-packages/flask/app.py", line 2292, in wsgi_app
    response = self.full_dispatch_request()
  File "/home/allin/Software/anaconda/envs/allen_blog/lib/python3.6/site-packages/flask/app.py", line 1815, in full_dispatch_request
    rv = self.handle_user_exception(e)
  File "/home/allin/Software/anaconda/envs/allen_blog/lib/python3.6/site-packages/flask/app.py", line 1718, in handle_user_exception
    reraise(exc_type, exc_value, tb)
  File "/home/allin/Software/anaconda/envs/allen_blog/lib/python3.6/site-packages/flask/_compat.py", line 35, in reraise
    raise value
  File "/home/allin/Software/anaconda/envs/allen_blog/lib/python3.6/site-packages/flask/app.py", line 1813, in full_dispatch_request
    rv = self.dispatch_request()
  File "/home/allin/Software/anaconda/envs/allen_blog/lib/python3.6/site-packages/flask/app.py", line 1799, in dispatch_request
    return self.view_functions[rule.endpoint](**req.view_args)
  File "/home/allin/Software/anaconda/envs/allen_blog/lib/python3.6/site-packages/flask_login/utils.py", line 261, in decorated_view
    return func(*args, **kwargs)
  File "/home/allin/Code/Python/Allen_blog/app/main/views.py", line 33, in index
    return render_template('index.html', title='Home page', posts=posts, form=form)
  File "/home/allin/Software/anaconda/envs/allen_blog/lib/python3.6/site-packages/flask/templating.py", line 135, in render_template
    context, ctx.app)
  File "/home/allin/Software/anaconda/envs/allen_blog/lib/python3.6/site-packages/flask/templating.py", line 117, in _render
    rv = template.render(context)
  File "/home/allin/Software/anaconda/envs/allen_blog/lib/python3.6/site-packages/jinja2/asyncsupport.py", line 76, in render
    return original_render(self, *args, **kwargs)
  File "/home/allin/Software/anaconda/envs/allen_blog/lib/python3.6/site-packages/jinja2/environment.py", line 1008, in render
    return self.environment.handle_exception(exc_info, True)
  File "/home/allin/Software/anaconda/envs/allen_blog/lib/python3.6/site-packages/jinja2/environment.py", line 780, in handle_exception
    reraise(exc_type, exc_value, tb)
  File "/home/allin/Software/anaconda/envs/allen_blog/lib/python3.6/site-packages/jinja2/_compat.py", line 37, in reraise
    raise value.with_traceback(tb)
  File "/home/allin/Code/Python/Allen_blog/app/templates/index.html", line 1, in top-level template code
    {% extends "base.html" %}
  File "/home/allin/Code/Python/Allen_blog/app/templates/base.html", line 31, in top-level template code
    {% block content %}{% endblock %}
  File "/home/allin/Code/Python/Allen_blog/app/templates/index.html", line 17, in block "content"
    {% for post in posts %}
  File "/home/allin/Software/anaconda/envs/allen_blog/lib/python3.6/site-packages/sqlalchemy/orm/dynamic.py", line 247, in __iter__
    return iter(self._clone(sess))
  File "/home/allin/Software/anaconda/envs/allen_blog/lib/python3.6/site-packages/sqlalchemy/orm/query.py", line 2988, in __iter__
    return self._execute_and_instances(context)
  File "/home/allin/Software/anaconda/envs/allen_blog/lib/python3.6/site-packages/sqlalchemy/orm/query.py", line 3011, in _execute_and_instances
    result = conn.execute(querycontext.statement, self._params)
  File "/home/allin/Software/anaconda/envs/allen_blog/lib/python3.6/site-packages/sqlalchemy/engine/base.py", line 948, in execute
    return meth(self, multiparams, params)
  File "/home/allin/Software/anaconda/envs/allen_blog/lib/python3.6/site-packages/sqlalchemy/sql/elements.py", line 269, in _execute_on_connection
    return connection._execute_clauseelement(self, multiparams, params)
  File "/home/allin/Software/anaconda/envs/allen_blog/lib/python3.6/site-packages/sqlalchemy/engine/base.py", line 1060, in _execute_clauseelement
    compiled_sql, distilled_params
  File "/home/allin/Software/anaconda/envs/allen_blog/lib/python3.6/site-packages/sqlalchemy/engine/base.py", line 1200, in _execute_context
    context)
  File "/home/allin/Software/anaconda/envs/allen_blog/lib/python3.6/site-packages/sqlalchemy/engine/base.py", line 1413, in _handle_dbapi_exception
    exc_info
  File "/home/allin/Software/anaconda/envs/allen_blog/lib/python3.6/site-packages/sqlalchemy/util/compat.py", line 265, in raise_from_cause
    reraise(type(exception), exception, tb=exc_tb, cause=cause)
  File "/home/allin/Software/anaconda/envs/allen_blog/lib/python3.6/site-packages/sqlalchemy/util/compat.py", line 248, in reraise
    raise value.with_traceback(tb)
  File "/home/allin/Software/anaconda/envs/allen_blog/lib/python3.6/site-packages/sqlalchemy/engine/base.py", line 1193, in _execute_context
    context)
  File "/home/allin/Software/anaconda/envs/allen_blog/lib/python3.6/site-packages/sqlalchemy/engine/default.py", line 509, in do_execute
    cursor.execute(statement, parameters)
sqlalchemy.exc.OperationalError: (sqlite3.OperationalError) no such table: parent [SQL: 'SELECT parent.id AS parent_id, parent.title AS parent_title, parent.body AS parent_body, parent.timestamp AS parent_timestamp, parent.user_id AS parent_user_id \nFROM parent \nWHERE ? = parent.user_id'] [parameters: (1,)] (Background on this error at: http://sqlalche.me/e/e3q8)
