2018-07-29 09:53:32,435 INFO: Microblog startup [in /home/allin/Code/Python/Allen_blog/app/my_extensions/file_logger.py:32]
2018-07-29 11:04:42,021 INFO: Microblog startup [in /home/allin/Code/Python/Allen_blog/app/my_extensions/file_logger.py:32]
2018-07-29 11:06:08,349 INFO: Microblog startup [in /home/allin/Code/Python/Allen_blog/app/my_extensions/file_logger.py:32]
2018-07-29 11:06:24,609 INFO: Microblog startup [in /home/allin/Code/Python/Allen_blog/app/my_extensions/file_logger.py:32]
2018-07-29 11:07:11,651 INFO: Microblog startup [in /home/allin/Code/Python/Allen_blog/app/my_extensions/file_logger.py:32]
2018-07-29 11:07:23,616 INFO: Microblog startup [in /home/allin/Code/Python/Allen_blog/app/my_extensions/file_logger.py:32]
2018-07-29 11:11:47,508 INFO: Microblog startup [in /home/allin/Code/Python/Allen_blog/app/my_extensions/file_logger.py:32]
2018-07-29 11:11:59,968 ERROR: Exception on /edit_profile/ [GET] [in /home/allin/Software/anaconda/envs/allen_blog/lib/python3.6/site-packages/flask/app.py:1761]
Traceback (most recent call last):
  File "/home/allin/Software/anaconda/envs/allen_blog/lib/python3.6/site-packages/flask/app.py", line 2292, in wsgi_app
    response = self.full_dispatch_request()
  File "/home/allin/Software/anaconda/envs/allen_blog/lib/python3.6/site-packages/flask/app.py", line 1815, in full_dispatch_request
    rv = self.handle_user_exception(e)
  File "/home/allin/Software/anaconda/envs/allen_blog/lib/python3.6/site-packages/flask/app.py", line 1718, in handle_user_exception
    reraise(exc_type, exc_value, tb)
  File "/home/allin/Software/anaconda/envs/allen_blog/lib/python3.6/site-packages/flask/_compat.py", line 35, in reraise
    raise value
  File "/home/allin/Software/anaconda/envs/allen_blog/lib/python3.6/site-packages/flask/app.py", line 1813, in full_dispatch_request
    rv = self.dispatch_request()
  File "/home/allin/Software/anaconda/envs/allen_blog/lib/python3.6/site-packages/flask/app.py", line 1799, in dispatch_request
    return self.view_functions[rule.endpoint](**req.view_args)
  File "/home/allin/Software/anaconda/envs/allen_blog/lib/python3.6/site-packages/flask_login/utils.py", line 261, in decorated_view
    return func(*args, **kwargs)
  File "/home/allin/Code/Python/Allen_blog/app/main/views.py", line 102, in edit_profile
    form = EditProfileForm()
  File "/home/allin/Software/anaconda/envs/allen_blog/lib/python3.6/site-packages/wtforms/form.py", line 212, in __call__
    return type.__call__(cls, *args, **kwargs)
TypeError: __init__() missing 1 required positional argument: 'original_username'
2018-07-29 11:12:25,551 INFO: Microblog startup [in /home/allin/Code/Python/Allen_blog/app/my_extensions/file_logger.py:32]
2018-07-29 11:12:30,205 ERROR: Exception on /edit_profile/ [GET] [in /home/allin/Software/anaconda/envs/allen_blog/lib/python3.6/site-packages/flask/app.py:1761]
Traceback (most recent call last):
  File "/home/allin/Software/anaconda/envs/allen_blog/lib/python3.6/site-packages/flask/app.py", line 2292, in wsgi_app
    response = self.full_dispatch_request()
  File "/home/allin/Software/anaconda/envs/allen_blog/lib/python3.6/site-packages/flask/app.py", line 1815, in full_dispatch_request
    rv = self.handle_user_exception(e)
  File "/home/allin/Software/anaconda/envs/allen_blog/lib/python3.6/site-packages/flask/app.py", line 1718, in handle_user_exception
    reraise(exc_type, exc_value, tb)
  File "/home/allin/Software/anaconda/envs/allen_blog/lib/python3.6/site-packages/flask/_compat.py", line 35, in reraise
    raise value
  File "/home/allin/Software/anaconda/envs/allen_blog/lib/python3.6/site-packages/flask/app.py", line 1813, in full_dispatch_request
    rv = self.dispatch_request()
  File "/home/allin/Software/anaconda/envs/allen_blog/lib/python3.6/site-packages/flask/app.py", line 1799, in dispatch_request
    return self.view_functions[rule.endpoint](**req.view_args)
  File "/home/allin/Software/anaconda/envs/allen_blog/lib/python3.6/site-packages/flask_login/utils.py", line 261, in decorated_view
    return func(*args, **kwargs)
  File "/home/allin/Code/Python/Allen_blog/app/main/views.py", line 102, in edit_profile
    form = EditProfileForm()
  File "/home/allin/Software/anaconda/envs/allen_blog/lib/python3.6/site-packages/wtforms/form.py", line 212, in __call__
    return type.__call__(cls, *args, **kwargs)
TypeError: __init__() missing 1 required positional argument: 'original_username'
2018-07-29 11:13:19,207 INFO: Microblog startup [in /home/allin/Code/Python/Allen_blog/app/my_extensions/file_logger.py:32]
2018-07-29 11:18:51,038 INFO: Microblog startup [in /home/allin/Code/Python/Allen_blog/app/my_extensions/file_logger.py:32]
2018-07-29 11:18:52,323 ERROR: Exception on / [GET] [in /home/allin/Software/anaconda/envs/allen_blog/lib/python3.6/site-packages/flask/app.py:1761]
Traceback (most recent call last):
  File "/home/allin/Software/anaconda/envs/allen_blog/lib/python3.6/site-packages/flask/app.py", line 2292, in wsgi_app
    response = self.full_dispatch_request()
  File "/home/allin/Software/anaconda/envs/allen_blog/lib/python3.6/site-packages/flask/app.py", line 1815, in full_dispatch_request
    rv = self.handle_user_exception(e)
  File "/home/allin/Software/anaconda/envs/allen_blog/lib/python3.6/site-packages/flask/app.py", line 1718, in handle_user_exception
    reraise(exc_type, exc_value, tb)
  File "/home/allin/Software/anaconda/envs/allen_blog/lib/python3.6/site-packages/flask/_compat.py", line 35, in reraise
    raise value
  File "/home/allin/Software/anaconda/envs/allen_blog/lib/python3.6/site-packages/flask/app.py", line 1813, in full_dispatch_request
    rv = self.dispatch_request()
  File "/home/allin/Software/anaconda/envs/allen_blog/lib/python3.6/site-packages/flask/app.py", line 1799, in dispatch_request
    return self.view_functions[rule.endpoint](**req.view_args)
  File "/home/allin/Software/anaconda/envs/allen_blog/lib/python3.6/site-packages/flask_login/utils.py", line 261, in decorated_view
    return func(*args, **kwargs)
  File "/home/allin/Code/Python/Allen_blog/app/main/views.py", line 33, in index
    return render_template('index.html', title='Home page', posts=posts, form=form)
  File "/home/allin/Software/anaconda/envs/allen_blog/lib/python3.6/site-packages/flask/templating.py", line 135, in render_template
    context, ctx.app)
  File "/home/allin/Software/anaconda/envs/allen_blog/lib/python3.6/site-packages/flask/templating.py", line 117, in _render
    rv = template.render(context)
  File "/home/allin/Software/anaconda/envs/allen_blog/lib/python3.6/site-packages/jinja2/asyncsupport.py", line 76, in render
    return original_render(self, *args, **kwargs)
  File "/home/allin/Software/anaconda/envs/allen_blog/lib/python3.6/site-packages/jinja2/environment.py", line 1008, in render
    return self.environment.handle_exception(exc_info, True)
  File "/home/allin/Software/anaconda/envs/allen_blog/lib/python3.6/site-packages/jinja2/environment.py", line 780, in handle_exception
    reraise(exc_type, exc_value, tb)
  File "/home/allin/Software/anaconda/envs/allen_blog/lib/python3.6/site-packages/jinja2/_compat.py", line 37, in reraise
    raise value.with_traceback(tb)
  File "/home/allin/Code/Python/Allen_blog/app/templates/index.html", line 1, in top-level template code
    {% extends "base.html" %}
  File "/home/allin/Code/Python/Allen_blog/app/templates/base.html", line 13, in top-level template code
    <a href="{{ url_for('main.explore') }}">Explore</a>
  File "/home/allin/Software/anaconda/envs/allen_blog/lib/python3.6/site-packages/flask/helpers.py", line 356, in url_for
    return appctx.app.handle_url_build_error(error, endpoint, values)
  File "/home/allin/Software/anaconda/envs/allen_blog/lib/python3.6/site-packages/flask/app.py", line 2061, in handle_url_build_error
    reraise(exc_type, exc_value, tb)
  File "/home/allin/Software/anaconda/envs/allen_blog/lib/python3.6/site-packages/flask/_compat.py", line 35, in reraise
    raise value
  File "/home/allin/Software/anaconda/envs/allen_blog/lib/python3.6/site-packages/flask/helpers.py", line 345, in url_for
    force_external=external)
  File "/home/allin/Software/anaconda/envs/allen_blog/lib/python3.6/site-packages/werkzeug/routing.py", line 1776, in build
    raise BuildError(endpoint, values, method, self)
werkzeug.routing.BuildError: Could not build url for endpoint 'main.explore'. Did you mean 'main.index' instead?
2018-07-29 11:20:22,264 INFO: Microblog startup [in /home/allin/Code/Python/Allen_blog/app/my_extensions/file_logger.py:32]
2018-07-29 11:20:25,595 ERROR: Exception on /explore [GET] [in /home/allin/Software/anaconda/envs/allen_blog/lib/python3.6/site-packages/flask/app.py:1761]
Traceback (most recent call last):
  File "/home/allin/Software/anaconda/envs/allen_blog/lib/python3.6/site-packages/flask/app.py", line 2292, in wsgi_app
    response = self.full_dispatch_request()
  File "/home/allin/Software/anaconda/envs/allen_blog/lib/python3.6/site-packages/flask/app.py", line 1815, in full_dispatch_request
    rv = self.handle_user_exception(e)
  File "/home/allin/Software/anaconda/envs/allen_blog/lib/python3.6/site-packages/flask/app.py", line 1718, in handle_user_exception
    reraise(exc_type, exc_value, tb)
  File "/home/allin/Software/anaconda/envs/allen_blog/lib/python3.6/site-packages/flask/_compat.py", line 35, in reraise
    raise value
  File "/home/allin/Software/anaconda/envs/allen_blog/lib/python3.6/site-packages/flask/app.py", line 1813, in full_dispatch_request
    rv = self.dispatch_request()
  File "/home/allin/Software/anaconda/envs/allen_blog/lib/python3.6/site-packages/flask/app.py", line 1799, in dispatch_request
    return self.view_functions[rule.endpoint](**req.view_args)
  File "/home/allin/Software/anaconda/envs/allen_blog/lib/python3.6/site-packages/flask_login/utils.py", line 261, in decorated_view
    return func(*args, **kwargs)
  File "/home/allin/Code/Python/Allen_blog/app/main/views.py", line 158, in explore
    posts = Post.query.order_by(Post.timestamp().desc()).all()
TypeError: 'InstrumentedAttribute' object is not callable
